Workbook

Sheet Resumo
C1: Obra | D1: Bancos | F1: B.D.I. | G1: Desconto | H1: Encargos Sociais
C2: REFORMA PREDIAL - BARRA DO GARÇAS - ADAPTAÇÃO DE SALAS | D2: SINAPI - 08/2025 - Mato Grosso | F2: 0.2454 | G2: 0.1737 | H2: Desonerado: embutido nos preços unitário dos insumos de mão de obra, de acordo com as bases.
A3: Planilha Orçamentária Resumida
A4: Item | C4: Descrição | G4: Quant. | H4: Total | I4: Peso (%)
A5: 1 | C5: ADMINISTRAÇÃO | G5: 1 | H5: =Sintético!J5 -> 9853.8754 | I5: 0.30143281
A6: 2 | C6: PAREDES E REVESTIMENTO | G6: 1 | H6: =Sintético!J9 -> 4531.4209 | I6: 0.13861744
A7: 3 | C7: PINTURA | G7: 1 | H7: =Sintético!J14 -> 4501.8146 | I7: 0.12976097
A8: 4 | C8: ESQUADRIAS | G8: 1 | H8: =Sintético!J23 -> 1749.2027 | I8: 0.051104531
A9: 5 | C9: ELÉTRICA | G9: 1 | H9: =Sintético!J27 -> 1353.9008 | I9: 0.041698294
A10: 6 | C10: REDE LÓGICA | G10: 1 | H10: =Sintético!J37 -> 10270.512 | I10: 0.31417785
A11: 7 | C11: LIMPEZA | G11: 1 | H11: =Sintético!J53 -> 758.67561 | I11: 0.0232081
E13: Total sem BDI | G13: =Sintético!H59 -> 31360.14
E14: Total do BDI | G14: =Sintético!H60 -> 8632.12
E15: Total Geral | G15: =Sintético!H61 -> -6972.8575
E16: Total Geral | G16: =Sintético!H62 -> 33019.402

Sheet Sintético
D1: Obra | E1: Bancos | G1: B.D.I. | H1: Desconto | I1: Encargos Sociais
D2: REFORMA PREDIAL - BARRA DO GARÇAS - ADAPTAÇÃO DE SALAS | E2: SINAPI - 08/2025 - Mato Grosso | G2: 0.2754 | H2: 0.1737 | I2: Desonerado: embutido nos preços unitário dos insumos de mão de obra, de acordo com as bases.
A3: Orçamento Sintético
A4: Item | B4: Código | C4: Banco | D4: Descrição | E4: Und | F4: Quant. | G4: Valor Unit | H4: Valor Unit com BDI | I4: Total | J4: Total com BDI e Desconto | K4: Peso (%)
A5: 1 | D5: ADMINISTRAÇÃO | F5: 1 | H5: 11925.3 | I5: 11925.3 | J5: =SUM(J6:J8) -> 9853.8754 | K5: 0.2981902
A6: 1.1 | B6: 90778 | C6: SINAPI | D6: ENGENHEIRO CIVIL DE OBRA PLENO COM ENCARGOS COMPLEMENTARES | E6: H | F6: 36 | G6: 118.93 | H6: 151.68 | I6: 5460.48 | J6: =I6-(I6*$H$2) -> 4511.9946 | K6: 0.13653842
A7: 1.2 | B7: 93572 | C7: SINAPI | D7: ENCARREGADO GERAL DE OBRAS COM ENCARGOS COMPLEMENTARES | E7: MES | F7: 1 | G7: 4797.39 | H7: 6118.59 | I7: 6118.59 | J7: =I7-(I7*$H$2) -> 5055.7909 | K7: 0.15299435
A8: 1.3 | B8: IP.DPMT.0036 | C8: Próprio | D8: TAXA ART/RRT - CREA/CAU | E8: VERBA | F8: 1 | G8: 271.47 | H8: 346.23 | I8: 346.23 | J8: =I8-(I8*$H$2) -> 286.08985 | K8: 0.0086574252
A9: 2 | D9: PAREDES E REVESTIMENTO | F9: 1 | H9: 5483.99 | I9: 5483.99 | J9: =SUM(J10:J13) -> 4531.4209 | K9: 0.13712628
A10: 2.1 | B10: CP.DPMT.01484 | C10: Próprio | D10: RODAPÉ CERÂMICO DE 10CM DE ALTURA COM PLACAS TIPO PORCELANATO DE DIMENSÕES 80X80 CM | E10: M | F10: 14.06 | G10: 49.51 | H10: 63.14 | I10: 887.74 | J10: =I10-(I10*$H$2) -> 733.53956 | K10: 0.022197795
A11: 2.2 | B11: 96361 | C11: SINAPI | D11: PAREDE COM SISTEMA EM CHAPAS DE GESSO PARA DRYWALL, USO INTERNO, COM DUAS FACES SIMPLES E ESTRUTURA METÁLICA COM GUIAS DUPLAS PARA PAREDES COM ÁREA LÍQUIDA MAIOR OU IGUAL A 6 M2, COM VÃOS. AF_07/2023_PS | E11: m² | F11: 21.09 | G11: 155.13 | H11: 197.85 | I11: 4172.65 | J11: =I11-(I11*$H$2) -> 3447.8607 | K11: 0.10433644
A12: 2.3 | B12: 97640 | C12: SINAPI | D12: REMOÇÃO DE FORROS DE DRYWALL, PVC E FIBROMINERAL, DE FORMA MANUAL, SEM REAPROVEITAMENTO. AF_09/2023 | E12: m² | F12: 4 | G12: 1.76 | H12: 2.24 | I12: 8.96 | J12: =I12-(I12*$H$2) -> 7.403648 | K12: 0.00022404335
A13: 2.4 | B13: 96114 | C13: SINAPI | D13: FORRO EM DRYWALL, PARA AMBIENTES COMERCIAIS, INCLUSIVE ESTRUTURA BIRECIONAL DE FIXAÇÃO. AF_08/2023_PS | E13: m² | F13: 4 | G13: 81.28 | H13: 103.66 | I13: 414.64 | J13: =I13-(I13*$H$2) -> 342.61703 | K13: 0.010368006
A14: 3 | D14: PINTURA | F14: 1 | H14: 5448.16 | I14: 5448.16 | J14: =SUM(J15:J22) -> 4501.8146 | K14: 0.13623036
A15: 3.1 | B15: 88497 | C15: SINAPI | D15: EMASSAMENTO COM MASSA LÁTEX, APLICAÇÃO EM PAREDE, DUAS DEMÃOS, LIXAMENTO MANUAL. AF_04/2023 | E15: m² | F15: 37.23 | G15: 16.67 | H15: 21.26 | I15: 791.5 | J15: =I15-(I15*$H$2) -> 654.01645 | K15: 0.01979133
A16: 3.2 | B16: 88489 | C16: SINAPI | D16: PINTURA LÁTEX ACRÍLICA PREMIUM, APLICAÇÃO MANUAL EM PAREDES, DUAS DEMÃOS. AF_04/2023 | E16: m² | F16: 190.68 | G16: 12.85 | H16: 16.38 | I16: 3123.33 | J16: =I16-(I16*$H$2) -> 2580.8076 | K16: 0.078098362
A17: 3.3 | B17: 88488 | C17: SINAPI | D17: PINTURA LÁTEX ACRÍLICA PREMIUM, APLICAÇÃO MANUAL EM TETO, DUAS DEMÃOS. AF_04/2023 | E17: m² | F17: 51.69 | G17: 14.93 | H17: 19.04 | I17: 984.17 | J17: =I17-(I17*$H$2) -> 813.21967 | K17: 0.024609012
A18: 3.4 | B18: 102227 | C18: SINAPI | D18: PINTURA TINTA DE ACABAMENTO (PIGMENTADA) A ÓLEO EM MADEIRA, 3 DEMÃOS. AF_01/2021 | E18: m² | F18: 3.36 | G18: 23.59 | H18: 30.08 | I18: 101.06 | J18: =I18-(I18*$H$2) -> 83.505878 | K18: 0.002526989
A19: 3.5 | B19: 102197 | C19: SINAPI | D19: PINTURA FUNDO NIVELADOR ALQUÍDICO BRANCO EM MADEIRA. AF_01/2021 | E19: m² | F19: 3.36 | G19: 25.94 | H19: 33.08 | I19: 111.14 | J19: =I19-(I19*$H$2) -> 91.834982 | K19: 0.0027790377
A20: 3.6 | B20: 102193 | C20: SINAPI | D20: LIXAMENTO DE MADEIRA PARA APLICAÇÃO DE FUNDO OU PINTURA. AF_01/2021 | E20: m² | F20: 3.36 | G20: 1.88 | H20: 2.39 | I20: 8.03 | J20: =I20-(I20*$H$2) -> 6.635189 | K20: 0.00020078885
A21: 3.7 | B21: 88485 | C21: SINAPI | D21: FUNDO SELADOR ACRÍLICO, APLICAÇÃO MANUAL EM PAREDE, UMA DEMÃO. AF_04/2023 | E21: m² | F21: 42.18 | G21: 3.36 | H21: 4.28 | I21: 180.53 | J21: =I21-(I21*$H$2) -> 149.17194 | K21: 0.0045141235
A22: 3.8 | B22: 88496 | C22: SINAPI | D22: EMASSAMENTO COM MASSA LÁTEX, APLICAÇÃO EM TETO, DUAS DEMÃOS, LIXAMENTO MANUAL. AF_04/2023 | E22: m² | F22: 4 | G22: 29.09 | H22: 37.1 | I22: 148.4 | J22: =I22-(I22*$H$2) -> 122.62292 | K22: 0.003710718
A23: 4 | D23: ESQUADRIAS | F23: 1 | H23: 2148.62 | I23: 2148.62 | J23: =SUM(J24:J26) -> 1749.2027 | K23: 0.053725896
A24: 4.1 | B24: 102179 | C24: SINAPI | D24: INSTALAÇÃO DE VIDRO TEMPERADO, E = 6 MM, ENCAIXADO EM PERFIL U. AF_01/2021_PS | E24: m² | F24: 1 | G24: 438.34 | H24: 559.05 | I24: 559.05 | J24: =I24-(I24*$H$2) -> 461.94301 | K24: 0.013978955
A25: 4.2 | B25: 100689 | C25: SINAPI | D25: KIT DE PORTA DE MADEIRA FRISADA, SEMI-OCA (LEVE OU MÉDIA), PADRÃO MÉDIO, 80X210CM, ESPESSURA DE 3,5CM, ITENS INCLUSOS: DOBRADIÇAS, MONTAGEM E INSTALAÇÃO DE BATENTE, FECHADURA COM EXECUÇÃO DO FURO - FORNECIMENTO E INSTALAÇÃO. AF_12/2019 | E25: UN | F25: 1 | G25: 1146.9 | H25: 1462.75 | I25: 1462.75 | J25: =I25-(I25*$H$2) -> 1208.6703 | K25: 0.036575827
A26: 4.3 | B26: 101965 | C26: SINAPI | D26: PEITORIL LINEAR EM GRANITO OU MÁRMORE, L = 15CM, ASSENTADO COM ARGAMASSA 1:6 COM ADITIVO. AF_11/2020 | E26: M | F26: 0.6 | G26: 124.3 | H26: 158.53 | I26: 95.11 | J26: =I26-(I26*$H$2) -> 78.589393 | K26: 0.0031711136
A27: 5 | D27: ELÉTRICA | F27: 1 | H27: 1638.51 | I27: 1638.51 | J27: =SUM(J28:J36) -> 1353.9008 | K27: 0.040970678
A28: 5.1 | B28: CP.DPMT.0293 | C28: Próprio | D28: TOMADA BAIXA SOBREPOR (2 MÓDULOS), 2P+T 10 A, INCLUINDO SUPORTE E PLACA - FORNECIMENTO E INSTALAÇÃO. AF_12/2015 | E28: UN | F28: 7 | G28: 32.15 | H28: 41 | I28: 287 | J28: =I28-(I28*$H$2) -> 237.1481 | K28: 0.0071763886
A29: 5.2 | B29: 91953 | C29: SINAPI | D29: INTERRUPTOR SIMPLES (1 MÓDULO), 10A/250V, INCLUINDO SUPORTE E PLACA - FORNECIMENTO E INSTALAÇÃO. AF_03/2023 | E29: UN | F29: 1 | G29: 27.27 | H29: 34.78 | I29: 34.78 | J29: =I29-(I29*$H$2) -> 28.738714 | K29: 0.00086966828
A30: 5.3 | B30: CP.DPMT.0992 | C30: Próprio | D30: INSTALAÇÃO DE LUMINÁRIA QUADRADA DE EMBUTIR, 40X40CM, TIPO LED, 32W | E30: UN | F30: 3 | G30: 102.16 | H30: 130.29 | I30: 390.87 | J30: =I30-(I30*$H$2) -> 322.97588 | K30: 0.0097736412
A31: 5.4 | B31: 91871 | C31: SINAPI | D31: ELETRODUTO RÍGIDO ROSCÁVEL, PVC, DN 25 MM (3/4"), PARA CIRCUITOS TERMINAIS, INSTALADO EM PAREDE - FORNECIMENTO E INSTALAÇÃO. AF_03/2023 | E31: M | F31: 5.94 | G31: 13.25 | H31: 16.89 | I31: 100.32 | J31: =I31-(I31*$H$2) -> 82.894416 | K31: 0.0025084854
A32: 5.5 | B32: 91834 | C32: SINAPI | D32: ELETRODUTO FLEXÍVEL CORRUGADO, PVC, DN 25 MM (3/4"), PARA CIRCUITOS TERMINAIS, INSTALADO EM FORRO - FORNECIMENTO E INSTALAÇÃO. AF_03/2023 | E32: M | F32: 7.94 | G32: 16.84 | H32: 21.47 | I32: 170.47 | J32: =I32-(I32*$H$2) -> 140.85936 | K32: 0.0042625748
A33: 5.6 | B33: 92008 | C33: SINAPI | D33: TOMADA BAIXA DE EMBUTIR (2 MÓDULOS), 2P+T 10 A, INCLUINDO SUPORTE E PLACA - FORNECIMENTO E INSTALAÇÃO. AF_03/2023 | E33: UN | F33: 4 | G33: 44.24 | H33: 56.42 | I33: 225.68 | J33: =I33-(I33*$H$2) -> 186.47938 | K33: 0.0056430919
A34: 5.7 | B34: 83387 | C34: SINAPI | D34: CAIXA DE PASSAGEM PVC 4X2" - FORNECIMENTO E INSTALACAO | E34: UN | F34: 4 | G34: 9.66 | H34: 12.32 | I34: 49.28 | J34: =I34-(I34*$H$2) -> 40.720064 | K34: 0.0012322384
A35: 5.8 | B35: 91926 | C35: SINAPI | D35: CABO DE COBRE FLEXÍVEL ISOLADO, 2,5 MM², ANTI-CHAMA 450/750 V, PARA CIRCUITOS TERMINAIS - FORNECIMENTO E INSTALAÇÃO. AF_03/2023 | E35: M | F35: 62.65 | G35: 4.55 | H35: 5.8 | I35: 363.37 | J35: =I35-(I35*$H$2) -> 300.25263 | K35: 0.0090860081
A36: 5.9 | B36: 83566 | C36: SINAPI | D36: TOMADA DE EMBUTIR 2P+T 20A/250V C/ PLACA - FORNECIMENTO E INSTALACAO | E36: UN | F36: 0.6 | G36: 21.88 | H36: 27.9 | I36: 16.74 | J36: =I36-(I36*$H$2) -> 13.832262 | K36: 0.000418581
A37: 6 | D37: REDE LÓGICA | F37: 1 | H37: 12429.52 | I37: 12429.52 | J37: =SUM(J38:J52) -> 10270.512 | K37: 0.31079814
A38: 6.1 | B38: 98302 | C38: SINAPI | D38: PATCH PANEL 24 PORTAS, CATEGORIA 6 - FORNECIMENTO E INSTALAÇÃO. AF_08/2025 | E38: UN | F38: 1 | G38: 1150.89 | H38: 1467.84 | I38: 1467.84 | J38: =I38-(I38*$H$2) -> 1212.8762 | K38: 0.036703102
A39: 6.2 | B39: 106084 | C39: SINAPI | D39: RACK DE PAREDE FECHADO DE 12 U EM CHAPA DE AÇO, 19", *570*MM - FORNECIMENTO E INSTALAÇÃO. AF_08/2025 | E39: UN | F39: 1 | G39: 664.97 | H39: 848.1 | I39: 848.1 | J39: =I39-(I39*$H$2) -> 700.78503 | K39: 0.021206603
A40: 6.3 | B40: CP.DPMT.0294 | C40: Próprio | D40: TOMADA DE REDE RJ45, CAT6 2 MODULOS, DE EMBUTIR - FORNECIMENTO E INSTALAÇÃO | E40: UN | F40: 3 | G40: 90.4 | H40: 115.29 | I40: 345.87 | J40: =I40-(I40*$H$2) -> 285.79238 | K40: 0.0086484235
...

Sheet Analítica
D1: Obra | E1: Bancos | G1: B.D.I. | H1: Desconto | I1: Encargos Sociais
D2: REFORMA PREDIAL - BARRA DO GARÇAS - ADAPTAÇÃO DE SALAS | E2: SINAPI - 08/2025 - Mato Grosso | G2: 0.2754 | H2: 0.1737 | I2: Desonerado: embutido nos preços unitário dos insumos de mão de obra, de acordo com as bases.
A3: Planilha Orçamentária Analítica
A4: 1 | D4: ADMINISTRAÇÃO | J4: 11925.3
A5: 1.1 | B5: Código | C5: Banco | D5: Descrição | E5: Tipo | G5: Und | H5: Quant. | I5: Valor Unit | J5: Total
A6: Composição | B6: 90778 | C6: SINAPI | D6: ENGENHEIRO CIVIL DE OBRA PLENO COM ENCARGOS COMPLEMENTARES | E6: SEDI - SERVIÇOS DIVERSOS | G6: H | H6: 1 | I6: 118.93 | J6: 118.93
A7: Composição Auxiliar | B7: 95403 | C7: SINAPI | D7: CURSO DE CAPACITAÇÃO PARA ENGENHEIRO CIVIL DE OBRA PLENO (ENCARGOS COMPLEMENTARES) - HORISTA | E7: SEDI - SERVIÇOS DIVERSOS | G7: H | H7: 1 | I7: 1.69 | J7: 1.69
A8: Insumo | B8: 00043462 | C8: SINAPI | D8: FERRAMENTAS - FAMILIA ENGENHEIRO CIVIL - HORISTA (ENCARGOS COMPLEMENTARES - COLETADO CAIXA) | E8: Equipamento | G8: H | H8: 1 | I8: 0.01 | J8: 0.01
A9: Insumo | B9: 00037373 | C9: SINAPI | D9: SEGURO - HORISTA (COLETADO CAIXA - ENCARGOS COMPLEMENTARES) | E9: Taxas | G9: H | H9: 1 | I9: 0.08 | J9: 0.08
A10: Insumo | B10: 00043486 | C10: SINAPI | D10: EPI - FAMILIA ENGENHEIRO CIVIL - HORISTA (ENCARGOS COMPLEMENTARES - COLETADO CAIXA) | E10: Equipamento | G10: H | H10: 1 | I10: 0.77 | J10: 0.77
A11: Insumo | B11: 00037372 | C11: SINAPI | D11: EXAMES - HORISTA (COLETADO CAIXA - ENCARGOS COMPLEMENTARES) | E11: Material | G11: H | H11: 1 | I11: 1.43 | J11: 1.43
A12: Insumo | B12: 00002707 | C12: SINAPI | D12: ENGENHEIRO CIVIL DE OBRA PLENO (HORISTA) | E12: Mão de Obra | G12: H | H12: 1 | I12: 114.95 | J12: 114.95
E13: MO sem LS => | F13: 116.64 | G13: LS => | H13: 0 | I13: MO com LS => | J13: 116.64
E14: Valor do BDI => | F14: 32.75 | H14: Valor com BDI => | J14: 151.68
G15: Quant. => | H15: 36,00 | I15: Preço Total => | J15: 5460.48
A17: 1.2 | B17: Código | C17: Banco | D17: Descrição | E17: Tipo | G17: Und | H17: Quant. | I17: Valor Unit | J17: Total
A18: Composição | B18: 93572 | C18: SINAPI | D18: ENCARREGADO GERAL DE OBRAS COM ENCARGOS COMPLEMENTARES | E18: SEDI - SERVIÇOS DIVERSOS | G18: MES | H18: 1 | I18: 4797.39 | J18: 4797.39
A19: Composição Auxiliar | B19: 95422 | C19: SINAPI | D19: CURSO DE CAPACITAÇÃO PARA ENCARREGADO GERAL DE OBRAS (ENCARGOS COMPLEMENTARES) - MENSALISTA | E19: SEDI - SERVIÇOS DIVERSOS | G19: MES | H19: 1 | I19: 66.86 | J19: 66.86
A20: Insumo | B20: 00040863 | C20: SINAPI | D20: EXAMES - MENSALISTA (COLETADO CAIXA - ENCARGOS COMPLEMENTARES) | E20: Material | G20: MES | H20: 1 | I20: 270.51 | J20: 270.51
A21: Insumo | B21: 00040818 | C21: SINAPI | D21: ENCARREGADO GERAL DE OBRAS (MENSALISTA) | E21: Mão de Obra | G21: MES | H21: 1 | I21: 4187.11 | J21: 4187.11
A22: Insumo | B22: 00043499 | C22: SINAPI | D22: EPI - FAMILIA ENCARREGADO GERAL - MENSALISTA (ENCARGOS COMPLEMENTARES - COLETADO CAIXA) | E22: Equipamento | G22: MES | H22: 1 | I22: 241.99 | J22: 241.99
A23: Insumo | B23: 00040864 | C23: SINAPI | D23: SEGURO - MENSALISTA (COLETADO CAIXA - ENCARGOS COMPLEMENTARES) | E23: Material | G23: MES | H23: 1 | I23: 15.46 | J23: 15.46
A24: Insumo | B24: 00043475 | C24: SINAPI | D24: FERRAMENTAS - FAMILIA ENCARREGADO GERAL - MENSALISTA (ENCARGOS COMPLEMENTARES - COLETADO CAIXA) | E24: Equipamento | G24: MES | H24: 1 | I24: 15.46 | J24: 15.46
E25: MO sem LS => | F25: 4253.97 | G25: LS => | H25: 0 | I25: MO com LS => | J25: 4253.97
E26: Valor do BDI => | F26: 1321.2 | H26: Valor com BDI => | J26: 6118.59
G27: Quant. => | H27: 1,00 | I27: Preço Total => | J27: 6118.59
B29: Código | C29: Banco | D29: Descrição | E29: Tipo | G29: Und | H29: Quant. | I29: Valor Unit | J29: Total
A30: Insumo | B30: IP.DPMT.0036 | C30: Próprio | D30: TAXA ART/RRT - CREA/CAU | E30: Taxas | G30: VERBA | H30: 1 | I30: 271.47 | J30: 271.47
E31: MO sem LS => | F31: 0 | G31: LS => | H31: 0 | I31: MO com LS => | J31: 0
E32: Valor do BDI => | H32: Valor com BDI => | J32: 346.23
G33: Quant. => | H33: 1,00 | I33: Preço Total => | J33: 346.23
A35: 2 | D35: PAREDES E REVESTIMENTO | J35: 5483.99
A36: 2.1 | B36: Código | C36: Banco | D36: Descrição | E36: Tipo | G36: Und | H36: Quant. | I36: Valor Unit | J36: Total
A37: Composição | B37: CP.DPMT.01484 | C37: Próprio | D37: RODAPÉ CERÂMICO DE 10CM DE ALTURA COM PLACAS TIPO PORCELANATO DE DIMENSÕES 80X80 CM | E37: PISO - PISOS | G37: M | H37: 1 | I37: 49.51 | J37: 49.51
A38: Composição Auxiliar | B38: 88316 | C38: SINAPI | D38: SERVENTE COM ENCARGOS COMPLEMENTARES | E38: SEDI - SERVIÇOS DIVERSOS | G38: H | H38: 0.2 | I38: 19.65 | J38: 3.93
A39: Composição Auxiliar | B39: 88256 | C39: SINAPI | D39: AZULEJISTA OU LADRILHEIRO COM ENCARGOS COMPLEMENTARES | E39: SEDI - SERVIÇOS DIVERSOS | G39: H | H39: 0.44 | I39: 24.25 | J39: 10.67
A40: Insumo | B40: 00034357 | C40: SINAPI | D40: REJUNTE CIMENTICIO, QUALQUER COR | E40: Material | G40: KG | H40: 0.14 | I40: 6.92 | J40: 0.96
A41: Insumo | B41: 00037595 | C41: SINAPI | D41: ARGAMASSA COLANTE TIPO AC III | E41: Material | G41: KG | H41: 1.87 | I41: 3.62 | J41: 6.76
A42: Insumo | B42: 00038195 | C42: SINAPI | D42: PISO EM PORCELANATO, BORDA RETA, LISO, MONOCOLOR, ACETINADO OU POLIDO, FORMATO MAIOR QUE 2025 CM2 | E42: Material | G42: M² | H42: 0.25 | I42: 108.78 | J42: 27.19
E43: MO sem LS => | F43: 10.62 | G43: LS => | H43: 0 | I43: MO com LS => | J43: 10.62
...

Sheet Mapa de Cotação
B1: Obra | C1: Bancos | E1: B.D.I. | F1: Descontos | G1: Encargos Sociais
B2: REFORMA PREDIAL - SEDE ADMINISTRATIVA | E2: 27,54% | F2: 0.2005 | G2: Não Desonerado: embutido nos preços unitário dos insumos de mão de obra, de acordo com as bases.
A3: Mapa de Cotação
A4: COTAÇÃO | B4: DESCRIÇÃO | C4: UNID. | D4: COTAÇÃO "A" | G4: COTAÇÃO "B" | J4: COTAÇÃO "C" | M4: MEDIANA VALOR (R$)
D5: LOJA "A" | E5: DATA | F5: PREÇO UNIT. | G5: LOJA "B" | H5: DATA | I5: PREÇO UNIT. | J5: LOJA"C" | K5: DATA | L5: PREÇO UNIT.
A6: IP.DPMT.0408 | B6: Guia de cabos 1u - aberto, pvc ou polímero, com mínimo 10 "fingers" | C6: UN | D6: https://www.kabum.com.br/produto/407793/guia-organizador-cabos-1u-x-19?srsltid=AfmBOoq9Z5zoJStje2-PL1lGfBUtsTcbmGmFeCohDXe2bhxzTG6Yr5MpJuU | E6: 45689 | F6: 32.05 | G6: https://www.leroymerlin.com.br/guia-organizador-cabos-1u-x-19_1570519276?region=outros | H6: 45689 | I6: 30.49 | J6: https://www.madeiramadeira.com.br/guia-organizador-cabos-1u-x-19-793174487.html | K6: 45689 | L6: 38.16 | M6: =MEDIAN(F6,I6,L6) -> 32.05
A7: IP.DPMT.0409 | B7: Organizador de cabos Velcro - 10m | C7: UN | D7: https://produto.mercadolivre.com.br/MLB-3994572772-fita-fecho-de-contato-organizador-de-cabos-rolo-10m-x-30mm-_JM?matt_tool=79588531&matt_word=&matt_source=google&matt_campaign_id=14302215549&matt_ad_group_id=150144483287&matt_match_type=&matt_network=g&matt_device=c&matt_creative=649447138068&matt_keyword=&matt_ad_position=&matt_ad_type=pla&matt_merchant_id=672335086&matt_product_id=MLB3994572772&matt_product_partition_id=1961639528326&matt_target_id=aud-1966490908987:pla-1961639528326&cq_src=google_ads&cq_cmp=14302215549&cq_net=g&cq_plt=gp&cq_med=pla&gad_source=4&gclid=Cj0KCQjw5ea1BhC6ARIsAEOG5pxAzRN6evIB7WIH1mvkc00Nxx68X1Pr4NH6dvk66eilC7oGiPtQFUAaAiz-EALw_wcB | E7: 45689 | F7: 7.99 | G7: https://www.americanas.com.br/produto/7470111657/fita-fecho-de-contato-organizador-de-cabos-preto-rolo-10m-x-30mm?offerId=66676680f85575c569224ddc&opn=YSMESP&epar=bp_pl_px_go_pmax_cec_3p_outros_geral_2&gclsrc=aw.ds&gad_source=4&gclid=Cj0KCQjw5ea1BhC6ARIsAEOG5pyOCtIiXUXH2Yrq9CjM-wYDZyGHL8Y6eWePTrf1zEzy8Y6eVgUKJ-YaAnsQEALw_wcB | H7: 45689 | I7: 10.86 | J7: https://www.47eletrica.com.br/fita-fecho-de-contato-organizador-de-cabos-cor-preto-rolo-10m-x-40mm?utm_source=google&utm_medium=Shopping&utm_campaign=fita-fecho-de-contato-organizador-de-cabos-cor-preto-rolo-10m-x-40mm&inStock&gad_source=4&gclid=Cj0KCQjw5ea1BhC6ARIsAEOG5pylcPlGoaDneNP10_b3owigOxlnEVe5Dthugr1y0h30N6s9pYbSyEsaArUAEALw_wcB#derivacao=951 | K7: 45689 | L7: 15.99 | M7: =MEDIAN(F7,I7,L7) -> 10.86
A8: IP.DPMT.0410 | B8: PDU 12 tomadas, NBR14136, 20A, com fusível e chave comutadora | C8: UN | D8: https://www.magazineluiza.com.br/pdu-20a-com-12-tomadas-padrao-nbr14136-8x10a-e-4x20a-casa-das-tomadas/p/gb381740b4/in/fdla/?utm_content=none_roa_ven_geral_pla_tod_3p&utm_source=google&utm_medium=cpc&seller_id=olistplus&srsltid=AfmBOoo3QRWgoOZH9uxgZLOyFqTayO46W_gY-kdx77UZc69CXdbxojBNkrk | E8: 45516 | F8: 222.35 | G8: https://www.americanas.com.br/produto/3148448071/pdu-10a-com-12-tomadas-45-graus-padrao-nbr14136-10a?offerId=6072a9b30c07044266cd4ee8&opn=YSMESP&srsltid=AfmBOorixwPCPvvXxSVsXjV8pLaX6oQ81HNj5nZ4nFjHWtVyNwhoH7WBrK4 | H8: 45516 | I8: 107.82 | J8: https://www.mercadolivre.com.br/pdu-28a-com-8-tomadas-verticais-padro-nbr14136-10a/p/MLB38799276?matt_tool=18956390&utm_source=google_shopping&utm_medium=organic&item_id=MLB4966575388&from=gshop | K8: 45516 | L8: 174.25 | M8: =MEDIAN(F8,I8,L8) -> 174.25

Sheet Cronograma
B1: Obra | C1: Bancos | D1: B.D.I. | E1: Defensoria
B2: REFORMA PREDIAL - BARRA DO GARÇAS - ADAPTAÇÃO DE SALAS | C2: SINAPI - 08/2025 - Mato Grosso | D2: 0.2754 | E2: 0.1737
A3: Cronograma Físico e Financeiro
A4: Item | B4: Descrição | C4: Total Por Etapa | D4: 30 DIAS
A5: 1 | B5: ADMINISTRAÇÃO | C5: =Resumo!H5 -> 9853.8754 | D5: =C5 -> 9853.8754
A6: 2 | B6: PAREDES E REVESTIMENTO | C6: =Resumo!H6 -> 4531.4209 | D6: =C6 -> 4531.4209
A7: 3 | B7: PINTURA | C7: =Resumo!H7 -> 4501.8146 | D7: =C7 -> 4501.8146
A8: 4 | B8: ESQUADRIAS | C8: =Resumo!H8 -> 1749.2027 | D8: =C8 -> 1749.2027
A9: 5 | B9: ELÉTRICA | C9: =Resumo!H9 -> 1353.9008 | D9: =C9 -> 1353.9008
A10: 6 | B10: REDE LÓGICA | C10: =Resumo!H10 -> 10270.512 | D10: =C10 -> 10270.512
A11: 7 | B11: LIMPEZA | C11: =Resumo!H11 -> 758.67561 | D11: =C11 -> 758.67561
A12: Porcentagem | D12: 1
A13: Custo | D13: =SUM(D5:D11) -> 33019.402
A14: Porcentagem Acumulado | D14: 1
A15: Custo Acumulado | D15: =D13 -> 33019.402
A18: _______________________________________________________________ Eng. Civil Adriano Augusto Assessor Especial
